Workbook

Sheet Matriz
A1: Fase | B1: Etapa | C1: No. Fase | D1: Orden del documento | E1: Iniciales de la Fase | F1: Iniciales Documento | G1: Clave | H1: Clave2 | I1: Entregables | J1: nombre del archivo | K1: Liga del documento
A2: Inicio | B2: Docuentacion | C2: 1 | D2: 10 | E2: IN | F2: ACP | G2: =CONCATENATE("PMOTI","_","0",Tabla3[[#This Row],[No. Fase]],Tabla3[[#This Row],[Orden del documento]],"_",Tabla3[[#This Row],[Iniciales de la Fase]],"_",Tabla3[[#This Row],[Iniciales Documento]]) -> PMOTI_0110_IN_ACP | H2: =CONCATENATE(Tabla3[[#This Row],[Clave]]) -> PMOTI_0110_IN_ACP | I2: ACTA DE CONSTITUCIÓN DEL PROYECTO | J2: =CONCATENATE(Tabla3[[#This Row],[Clave]]," ",Tabla3[[#This Row],[Entregables]]) -> PMOTI_0110_IN_ACP ACTA DE CONSTITUCIÓN DEL PROYECTO | K2: PMOTI_0110_IN_ACP ACTA DE CONSTITUCIÓN DEL PROYECTO.docx
A3: Inicio | B3: Docuentacion | C3: 1 | D3: =D2+10 -> 20 | E3: IN | F3: EGI | G3: =CONCATENATE("PMOTI","_","0",Tabla3[[#This Row],[No. Fase]],Tabla3[[#This Row],[Orden del documento]],"_",Tabla3[[#This Row],[Iniciales de la Fase]],"_",Tabla3[[#This Row],[Iniciales Documento]]) -> PMOTI_0120_IN_EGI | H3: =CONCATENATE(Tabla3[[#This Row],[Clave]]) -> PMOTI_0120_IN_EGI | I3: Estrategia de Gestión de Interesados | J3: =CONCATENATE(Tabla3[[#This Row],[Clave]]," ",Tabla3[[#This Row],[Entregables]]) -> PMOTI_0120_IN_EGI Estrategia de Gestión de Interesados | K3: PMOTI_0120_IN_EGI Estrategia de Gestión de Interesados.docx
A4: Inicio | B4: Docuentacion | C4: 1 | D4: =D3+10 -> 30 | E4: IN | F4: JEI | G4: =CONCATENATE("PMOTI","_","0",Tabla3[[#This Row],[No. Fase]],Tabla3[[#This Row],[Orden del documento]],"_",Tabla3[[#This Row],[Iniciales de la Fase]],"_",Tabla3[[#This Row],[Iniciales Documento]]) -> PMOTI_0130_IN_JEI | H4: =CONCATENATE(Tabla3[[#This Row],[Clave]]) -> PMOTI_0130_IN_JEI | I4: Junta de Entregables de Inicio | J4: =CONCATENATE(Tabla3[[#This Row],[Clave]]," ",Tabla3[[#This Row],[Entregables]]) -> PMOTI_0130_IN_JEI Junta de Entregables de Inicio | K4: PMOTI_0130_IN_JEI Junta de Entregables de Inicio.docx
A5: Inicio | B5: Seguimiento y control | C5: 1 | D5: =D4+10 -> 40 | E5: IN | F5: SC | G5: =CONCATENATE("PMOTI","_","0",Tabla3[[#This Row],[No. Fase]],Tabla3[[#This Row],[Orden del documento]],"_",Tabla3[[#This Row],[Iniciales de la Fase]],"_",Tabla3[[#This Row],[Iniciales Documento]]) -> PMOTI_0140_IN_SC | H5: =CONCATENATE(Tabla3[[#This Row],[Clave]]) -> PMOTI_0140_IN_SC | I5: Solicitud de Cambio Nº | J5: =CONCATENATE(Tabla3[[#This Row],[Clave]]," ",Tabla3[[#This Row],[Entregables]]) -> PMOTI_0140_IN_SC Solicitud de Cambio Nº | K5: PMOTI_0140_IN_SC Solicitud de Cambio Nº.docx
A6: Inicio | B6: Seguimiento y control | C6: 1 | D6: =D5+10 -> 50 | E6: IN | F6: ID | G6: =CONCATENATE("PMOTI","_","0",Tabla3[[#This Row],[No. Fase]],Tabla3[[#This Row],[Orden del documento]],"_",Tabla3[[#This Row],[Iniciales de la Fase]],"_",Tabla3[[#This Row],[Iniciales Documento]]) -> PMOTI_0150_IN_ID | H6: =CONCATENATE(Tabla3[[#This Row],[Clave]]) -> PMOTI_0150_IN_ID | I6: Informe de Desempeño Nº | J6: =CONCATENATE(Tabla3[[#This Row],[Clave]]," ",Tabla3[[#This Row],[Entregables]]) -> PMOTI_0150_IN_ID Informe de Desempeño Nº | K6: PMOTI_0150_IN_ID Informe de Desempeño Nº.docx
A7: Inicio | B7: Cierre | C7: 1 | D7: =D6+10 -> 60 | E7: IN | F7: ACFI | G7: =CONCATENATE("PMOTI","_","0",Tabla3[[#This Row],[No. Fase]],Tabla3[[#This Row],[Orden del documento]],"_",Tabla3[[#This Row],[Iniciales de la Fase]],"_",Tabla3[[#This Row],[Iniciales Documento]]) -> PMOTI_0160_IN_ACFI | H7: =CONCATENATE(Tabla3[[#This Row],[Clave]]) -> PMOTI_0160_IN_ACFI | I7: Acta de Cierre de la Fase de Inicio | J7: =CONCATENATE(Tabla3[[#This Row],[Clave]]," ",Tabla3[[#This Row],[Entregables]]) -> PMOTI_0160_IN_ACFI Acta de Cierre de la Fase de Inicio | K7: PMOTI_0160_IN_ACFI Acta de Cierre de la Fase de Inicio.docx
A8: Planeación | B8: Docuentacion | C8: 2 | D8: 10 | E8: PL | F8: PGC | G8: =CONCATENATE("PMOTI","_","0",Tabla3[[#This Row],[No. Fase]],Tabla3[[#This Row],[Orden del documento]],"_",Tabla3[[#This Row],[Iniciales de la Fase]],"_",Tabla3[[#This Row],[Iniciales Documento]]) -> PMOTI_0210_PL_PGC | H8: =CONCATENATE(Tabla3[[#This Row],[Clave]]) -> PMOTI_0210_PL_PGC | I8: Plan de Gestión de la Configuracion | J8: =CONCATENATE(Tabla3[[#This Row],[Clave]]," ",Tabla3[[#This Row],[Entregables]]) -> PMOTI_0210_PL_PGC Plan de Gestión de la Configuracion | K8: PMOTI_0210_PL_PGC Plan de Gestión de la Configuracion.docx
A9: Planeación | B9: Docuentacion | C9: 2 | D9: =D8+10 -> 20 | E9: PL | F9: PGC | G9: =CONCATENATE("PMOTI","_","0",Tabla3[[#This Row],[No. Fase]],Tabla3[[#This Row],[Orden del documento]],"_",Tabla3[[#This Row],[Iniciales de la Fase]],"_",Tabla3[[#This Row],[Iniciales Documento]]) -> PMOTI_0220_PL_PGC | H9: =CONCATENATE(Tabla3[[#This Row],[Clave]]) -> PMOTI_0220_PL_PGC | I9: Plan de Gestión de Cambios | J9: =CONCATENATE(Tabla3[[#This Row],[Clave]]," ",Tabla3[[#This Row],[Entregables]]) -> PMOTI_0220_PL_PGC Plan de Gestión de Cambios | K9: PMOTI_0220_PL_PGC Plan de Gestión de Cambios.docx
A10: Planeación | B10: Docuentacion | C10: 2 | D10: =D9+10 -> 30 | E10: PL | F10: DA | G10: =CONCATENATE("PMOTI","_","0",Tabla3[[#This Row],[No. Fase]],Tabla3[[#This Row],[Orden del documento]],"_",Tabla3[[#This Row],[Iniciales de la Fase]],"_",Tabla3[[#This Row],[Iniciales Documento]]) -> PMOTI_0230_PL_DA | H10: =CONCATENATE(Tabla3[[#This Row],[Clave]]) -> PMOTI_0230_PL_DA | I10: Declaración de Alcance | J10: =CONCATENATE(Tabla3[[#This Row],[Clave]]," ",Tabla3[[#This Row],[Entregables]]) -> PMOTI_0230_PL_DA Declaración de Alcance | K10: PMOTI_0230_PL_DA DECLARACIÓN DEL ALCANCE.docx
A11: Planeación | B11: Docuentacion | C11: 2 | D11: =D10+10 -> 40 | E11: PL | F11: DR | G11: =CONCATENATE("PMOTI","_","0",Tabla3[[#This Row],[No. Fase]],Tabla3[[#This Row],[Orden del documento]],"_",Tabla3[[#This Row],[Iniciales de la Fase]],"_",Tabla3[[#This Row],[Iniciales Documento]]) -> PMOTI_0240_PL_DR | H11: =CONCATENATE(Tabla3[[#This Row],[Clave]]) -> PMOTI_0240_PL_DR | I11: Documentación de Requisitos | J11: =CONCATENATE(Tabla3[[#This Row],[Clave]]," ",Tabla3[[#This Row],[Entregables]]) -> PMOTI_0240_PL_DR Documentación de Requisitos | K11: PMOTI_0240_PL_DR DOCUMENTACIÓN DE REQUISITOS.docx
A12: Planeación | B12: Docuentacion | C12: 2 | D12: =D11+10 -> 50 | E12: PL | F12: PGR | G12: =CONCATENATE("PMOTI","_","0",Tabla3[[#This Row],[No. Fase]],Tabla3[[#This Row],[Orden del documento]],"_",Tabla3[[#This Row],[Iniciales de la Fase]],"_",Tabla3[[#This Row],[Iniciales Documento]]) -> PMOTI_0250_PL_PGR | H12: =CONCATENATE(Tabla3[[#This Row],[Clave]]) -> PMOTI_0250_PL_PGR | I12: Plan de Gestión de Requisitos | J12: =CONCATENATE(Tabla3[[#This Row],[Clave]]," ",Tabla3[[#This Row],[Entregables]]) -> PMOTI_0250_PL_PGR Plan de Gestión de Requisitos | K12: PMOTI_0250_PL_PGR PLAN DE GESTIÓN DE REQUISITOS.docx
A13: Planeación | B13: Docuentacion | C13: 2 | D13: =D12+10 -> 60 | E13: PL | F13: MTR | G13: =CONCATENATE("PMOTI","_","0",Tabla3[[#This Row],[No. Fase]],Tabla3[[#This Row],[Orden del documento]],"_",Tabla3[[#This Row],[Iniciales de la Fase]],"_",Tabla3[[#This Row],[Iniciales Documento]]) -> PMOTI_0260_PL_MTR | H13: =CONCATENATE(Tabla3[[#This Row],[Clave]]) -> PMOTI_0260_PL_MTR | I13: Matriz de Trazabilidad de Requisitos | J13: =CONCATENATE(Tabla3[[#This Row],[Clave]]," ",Tabla3[[#This Row],[Entregables]]) -> PMOTI_0260_PL_MTR Matriz de Trazabilidad de Requisitos | K13: PMOTI_0260_PL_MTR MATRIZ DE TRAZABILIDAD DE REQUISITOS.docx
A14: Planeación | B14: Docuentacion | C14: 2 | D14: =D13+10 -> 70 | E14: PL | F14: PGP | G14: =CONCATENATE("PMOTI","_","0",Tabla3[[#This Row],[No. Fase]],Tabla3[[#This Row],[Orden del documento]],"_",Tabla3[[#This Row],[Iniciales de la Fase]],"_",Tabla3[[#This Row],[Iniciales Documento]]) -> PMOTI_0270_PL_PGP | H14: =CONCATENATE(Tabla3[[#This Row],[Clave]]) -> PMOTI_0270_PL_PGP | I14: Plan de Gestión de Proyecto | J14: =CONCATENATE(Tabla3[[#This Row],[Clave]]," ",Tabla3[[#This Row],[Entregables]]) -> PMOTI_0270_PL_PGP Plan de Gestión de Proyecto | K14: PMOTI_0270_PL_PGP PLAN DE GESTIÓN DE PROYECTO.docx
A15: Planeación | B15: Docuentacion | C15: 2 | D15: =D14+10 -> 80 | E15: PL | F15: PGA | G15: =CONCATENATE("PMOTI","_","0",Tabla3[[#This Row],[No. Fase]],Tabla3[[#This Row],[Orden del documento]],"_",Tabla3[[#This Row],[Iniciales de la Fase]],"_",Tabla3[[#This Row],[Iniciales Documento]]) -> PMOTI_0280_PL_PGA | H15: =CONCATENATE(Tabla3[[#This Row],[Clave]]) -> PMOTI_0280_PL_PGA | I15: Plan de Gestión de Alcance | J15: =CONCATENATE(Tabla3[[#This Row],[Clave]]," ",Tabla3[[#This Row],[Entregables]]) -> PMOTI_0280_PL_PGA Plan de Gestión de Alcance | K15: PMOTI_0280_PL_PGA PLAN DE GESTIÓN DE ALCANCE.docx
A16: Planeación | B16: Docuentacion | C16: 2 | D16: =D15+10 -> 90 | E16: PL | F16: EDT | G16: =CONCATENATE("PMOTI","_","0",Tabla3[[#This Row],[No. Fase]],Tabla3[[#This Row],[Orden del documento]],"_",Tabla3[[#This Row],[Iniciales de la Fase]],"_",Tabla3[[#This Row],[Iniciales Documento]]) -> PMOTI_0290_PL_EDT | H16: =CONCATENATE(Tabla3[[#This Row],[Clave]]) -> PMOTI_0290_PL_EDT | I16: EDT | J16: =CONCATENATE(Tabla3[[#This Row],[Clave]]," ",Tabla3[[#This Row],[Entregables]]) -> PMOTI_0290_PL_EDT EDT | K16: PMOTI_0290_PL_EDT EDT o WBS DEL PROYECTO.docx
A17: Planeación | B17: Docuentacion | C17: 2 | D17: =D16+10 -> 100 | E17: PL | F17: DEDT | G17: =CONCATENATE("PMOTI","_","0",Tabla3[[#This Row],[No. Fase]],Tabla3[[#This Row],[Orden del documento]],"_",Tabla3[[#This Row],[Iniciales de la Fase]],"_",Tabla3[[#This Row],[Iniciales Documento]]) -> PMOTI_02100_PL_DEDT | H17: =CONCATENATE(Tabla3[[#This Row],[Clave]]) -> PMOTI_02100_PL_DEDT | I17: Diccionario EDT (simplificado) | J17: =CONCATENATE(Tabla3[[#This Row],[Clave]]," ",Tabla3[[#This Row],[Entregables]]) -> PMOTI_02100_PL_DEDT Diccionario EDT (simplificado) | K17: PMOTI_02100_PL_DEDT DICCIONARIO WBS o EDT (simplificado).docx
A18: Planeación | B18: Docuentacion | C18: 2 | D18: =D17+10 -> 110 | E18: PL | F18: DR | G18: =CONCATENATE("PMOTI","_","0",Tabla3[[#This Row],[No. Fase]],Tabla3[[#This Row],[Orden del documento]],"_",Tabla3[[#This Row],[Iniciales de la Fase]],"_",Tabla3[[#This Row],[Iniciales Documento]]) -> PMOTI_02110_PL_DR | H18: =CONCATENATE(Tabla3[[#This Row],[Clave]]) -> PMOTI_02110_PL_DR | I18: Diagrama de Red | J18: =CONCATENATE(Tabla3[[#This Row],[Clave]]," ",Tabla3[[#This Row],[Entregables]]) -> PMOTI_02110_PL_DR Diagrama de Red | K18: PMOTI_02110_PL_DRFGPR_110_04 DIAGRAMA DE RED DEL PROYECTO.docx
A19: Planeación | B19: Docuentacion | C19: 2 | D19: =D18+10 -> 120 | E19: PL | F19: ER | G19: =CONCATENATE("PMOTI","_","0",Tabla3[[#This Row],[No. Fase]],Tabla3[[#This Row],[Orden del documento]],"_",Tabla3[[#This Row],[Iniciales de la Fase]],"_",Tabla3[[#This Row],[Iniciales Documento]]) -> PMOTI_02120_PL_ER | H19: =CONCATENATE(Tabla3[[#This Row],[Clave]]) -> PMOTI_02120_PL_ER | I19: Estimación de Recursos | J19: =CONCATENATE(Tabla3[[#This Row],[Clave]]," ",Tabla3[[#This Row],[Entregables]]) -> PMOTI_02120_PL_ER Estimación de Recursos | K19: PMOTI_02120_PL_ER ESTIMACIÓN DE RECURSOS Y DURACIONES.docx
A20: Planeación | B20: Docuentacion | C20: 2 | D20: =D19+10 -> 130 | E20: PL | F20: CP | G20: =CONCATENATE("PMOTI","_","0",Tabla3[[#This Row],[No. Fase]],Tabla3[[#This Row],[Orden del documento]],"_",Tabla3[[#This Row],[Iniciales de la Fase]],"_",Tabla3[[#This Row],[Iniciales Documento]]) -> PMOTI_02130_PL_CP | H20: =CONCATENATE(Tabla3[[#This Row],[Clave]]) -> PMOTI_02130_PL_CP | I20: Cronograma del Proyecto | J20: =CONCATENATE(Tabla3[[#This Row],[Clave]]," ",Tabla3[[#This Row],[Entregables]]) -> PMOTI_02130_PL_CP Cronograma del Proyecto | K20: PMOTI_02130_PL_CP CRONOGRAMA DEL PROYECTO.docx
... A25: Planeación | B25: Seguimiento y control | C25: 2 | D25: =D24+10 -> 180 | E25: PL | F25: SC | G25: =CONCATENATE("PMOTI","_","0",Tabla3[[#This Row],[No. Fase]],Tabla3[[#This Row],[Orden del documento]],"_",Tabla3[[#This Row],[Iniciales de la Fase]],"_",Tabla3[[#This Row],[Iniciales Documento]]) -> PMOTI_02180_PL_SC | H25: =CONCATENATE(Tabla3[[#This Row],[Clave]]) -> PMOTI_02180_PL_SC | I25: Solicitud de Cambio Nº | J25: =CONCATENATE(Tabla3[[#This Row],[Clave]]," ",Tabla3[[#This Row],[Entregables]]) -> PMOTI_02180_PL_SC Solicitud de Cambio Nº | K25: PMOTI_02180_PL_SC Solicitud de Cambio Nº.docx
A26: Planeación | B26: Seguimiento y control | C26: 2 | D26: =D25+10 -> 190 | E26: PL | F26: RCT | G26: =CONCATENATE("PMOTI","_","0",Tabla3[[#This Row],[No. Fase]],Tabla3[[#This Row],[Orden del documento]],"_",Tabla3[[#This Row],[Iniciales de la Fase]],"_",Tabla3[[#This Row],[Iniciales Documento]]) -> PMOTI_02190_PL_RCT | H26: =CONCATENATE(Tabla3[[#This Row],[Clave]]) -> PMOTI_02190_PL_RCT | I26: Reunion de Control de Trabajo Nº | J26: =CONCATENATE(Tabla3[[#This Row],[Clave]]," ",Tabla3[[#This Row],[Entregables]]) -> PMOTI_02190_PL_RCT Reunion de Control de Trabajo Nº
A27: Planeación | B27: Seguimiento y control | C27: 2 | D27: =D26+10 -> 200 | E27: PL | F27: RC | G27: =CONCATENATE("PMOTI","_","0",Tabla3[[#This Row],[No. Fase]],Tabla3[[#This Row],[Orden del documento]],"_",Tabla3[[#This Row],[Iniciales de la Fase]],"_",Tabla3[[#This Row],[Iniciales Documento]]) -> PMOTI_02200_PL_RC | H27: =CONCATENATE(Tabla3[[#This Row],[Clave]]) -> PMOTI_02200_PL_RC | I27: Reunion de Control Nº | J27: =CONCATENATE(Tabla3[[#This Row],[Clave]]," ",Tabla3[[#This Row],[Entregables]]) -> PMOTI_02200_PL_RC Reunion de Control Nº | K27: PMOTI_02200_PL_RC Reunion de Control Nº.docx
A28: Planeación | B28: Cierre | C28: 2 | D28: =D27+10 -> 210 | E28: PL | F28: ACFP | G28: =CONCATENATE("PMOTI","_","0",Tabla3[[#This Row],[No. Fase]],Tabla3[[#This Row],[Orden del documento]],"_",Tabla3[[#This Row],[Iniciales de la Fase]],"_",Tabla3[[#This Row],[Iniciales Documento]]) -> PMOTI_02210_PL_ACFP | H28: =CONCATENATE(Tabla3[[#This Row],[Clave]]) -> PMOTI_02210_PL_ACFP | I28: Acta de Cierre de la Fase de Planeación | J28: =CONCATENATE(Tabla3[[#This Row],[Clave]]," ",Tabla3[[#This Row],[Entregables]]) -> PMOTI_02210_PL_ACFP Acta de Cierre de la Fase de Planeación | K28: PMOTI_02210_PL_ACFI ACTA DE ACEPTACIÓN DE PLANEACION.docx
A29: Ejecución | B29: Docuentacion | C29: 3 | D29: 10 | E29: EJ | F29: PGP | G29: =CONCATENATE("PMOTI","_","0",Tabla3[[#This Row],[No. Fase]],Tabla3[[#This Row],[Orden del documento]],"_",Tabla3[[#This Row],[Iniciales de la Fase]],"_",Tabla3[[#This Row],[Iniciales Documento]]) -> PMOTI_0310_EJ_PGP | H29: =CONCATENATE(Tabla3[[#This Row],[Clave]]) -> PMOTI_0310_EJ_PGP | I29: Plan de Gestión de Proyecto | J29: =CONCATENATE(Tabla3[[#This Row],[Clave]]," ",Tabla3[[#This Row],[Entregables]]) -> PMOTI_0310_EJ_PGP Plan de Gestión de Proyecto | K29: PMOTI_0310_EJ_PGP Plan de Gestión de Proyecto.docx
A30: Ejecución | B30: Docuentacion | C30: 3 | D30: =10+D29 -> 20 | E30: EJ | F30: JEE | G30: =CONCATENATE("PMOTI","_","0",Tabla3[[#This Row],[No. Fase]],Tabla3[[#This Row],[Orden del documento]],"_",Tabla3[[#This Row],[Iniciales de la Fase]],"_",Tabla3[[#This Row],[Iniciales Documento]]) -> PMOTI_0320_EJ_JEE | H30: =CONCATENATE(Tabla3[[#This Row],[Clave]]) -> PMOTI_0320_EJ_JEE | I30: Junta de Entregables de Ejecución | J30: =CONCATENATE(Tabla3[[#This Row],[Clave]]," ",Tabla3[[#This Row],[Entregables]]) -> PMOTI_0320_EJ_JEE Junta de Entregables de Ejecución | K30: PMOTI_0320_EJ_JEE Junta de Entregables de Ejecución.docx
A31: Ejecución | B31: Seguimiento y control | C31: 3 | D31: =10+D30 -> 30 | E31: EJ | F31: SC | G31: =CONCATENATE("PMOTI","_","0",Tabla3[[#This Row],[No. Fase]],Tabla3[[#This Row],[Orden del documento]],"_",Tabla3[[#This Row],[Iniciales de la Fase]],"_",Tabla3[[#This Row],[Iniciales Documento]]) -> PMOTI_0330_EJ_SC | H31: =CONCATENATE(Tabla3[[#This Row],[Clave]]) -> PMOTI_0330_EJ_SC | I31: Solicitud de Cambio Nº | J31: =CONCATENATE(Tabla3[[#This Row],[Clave]]," ",Tabla3[[#This Row],[Entregables]]) -> PMOTI_0330_EJ_SC Solicitud de Cambio Nº | K31: PMOTI_0330_EJ_SC Solicitud de Cambio Nº.docx
A32: Ejecución | B32: Seguimiento y control | C32: 3 | D32: =10+D31 -> 40 | E32: EJ | F32: ID | G32: =CONCATENATE("PMOTI","_","0",Tabla3[[#This Row],[No. Fase]],Tabla3[[#This Row],[Orden del documento]],"_",Tabla3[[#This Row],[Iniciales de la Fase]],"_",Tabla3[[#This Row],[Iniciales Documento]]) -> PMOTI_0340_EJ_ID | H32: =CONCATENATE(Tabla3[[#This Row],[Clave]]) -> PMOTI_0340_EJ_ID | I32: Informe de Desempeño Nº | J32: =CONCATENATE(Tabla3[[#This Row],[Clave]]," ",Tabla3[[#This Row],[Entregables]]) -> PMOTI_0340_EJ_ID Informe de Desempeño Nº | K32: PMOTI_0340_EJ_ID Informe de Desempeño Nº.docx
A33: Ejecución | B33: Seguimiento y control | C33: 3 | D33: =10+D32 -> 50 | E33: EJ | F33: RC | G33: =CONCATENATE("PMOTI","_","0",Tabla3[[#This Row],[No. Fase]],Tabla3[[#This Row],[Orden del documento]],"_",Tabla3[[#This Row],[Iniciales de la Fase]],"_",Tabla3[[#This Row],[Iniciales Documento]]) -> PMOTI_0350_EJ_RC | H33: =CONCATENATE(Tabla3[[#This Row],[Clave]]) -> PMOTI_0350_EJ_RC | I33: Reunion de Control Nº | J33: =CONCATENATE(Tabla3[[#This Row],[Clave]]," ",Tabla3[[#This Row],[Entregables]]) -> PMOTI_0350_EJ_RC Reunion de Control Nº | K33: PMOTI_0350_EJ_RC Reunion de Control Nº.docx
A34: Ejecución | B34: Seguimiento y control | C34: 3 | D34: =10+D33 -> 60 | E34: EJ | F34: ECG | G34: =CONCATENATE("PMOTI","_","0",Tabla3[[#This Row],[No. Fase]],Tabla3[[#This Row],[Orden del documento]],"_",Tabla3[[#This Row],[Iniciales de la Fase]],"_",Tabla3[[#This Row],[Iniciales Documento]]) -> PMOTI_0360_EJ_ECG | H34: =CONCATENATE(Tabla3[[#This Row],[Clave]]) -> PMOTI_0360_EJ_ECG | I34: Evaluación de Competencias Generales Nº | J34: =CONCATENATE(Tabla3[[#This Row],[Clave]]," ",Tabla3[[#This Row],[Entregables]]) -> PMOTI_0360_EJ_ECG Evaluación de Competencias Generales Nº | K34: PMOTI_0360_EJ_ECG Evaluación de Competencias Generales Nº.docx
A35: Ejecución | B35: Cierre | C35: 3 | D35: =10+D34 -> 70 | E35: EJ | F35: ACFE | G35: =CONCATENATE("PMOTI","_","0",Tabla3[[#This Row],[No. Fase]],Tabla3[[#This Row],[Orden del documento]],"_",Tabla3[[#This Row],[Iniciales de la Fase]],"_",Tabla3[[#This Row],[Iniciales Documento]]) -> PMOTI_0370_EJ_ACFE | H35: =CONCATENATE(Tabla3[[#This Row],[Clave]]) -> PMOTI_0370_EJ_ACFE | I35: Acta de Cierre de la Fase de Ejecución | J35: =CONCATENATE(Tabla3[[#This Row],[Clave]]," ",Tabla3[[#This Row],[Entregables]]) -> PMOTI_0370_EJ_ACFE Acta de Cierre de la Fase de Ejecución | K35: PMOTI_0370_EJ_ACFE Acta de Cierre de la Fase de Ejecución.docx
A36: Cierre | B36: Docuentacion | C36: 4 | D36: 10 | E36: CI | F36: AAP | G36: =CONCATENATE("PMOTI","_","0",Tabla3[[#This Row],[No. Fase]],Tabla3[[#This Row],[Orden del documento]],"_",Tabla3[[#This Row],[Iniciales de la Fase]],"_",Tabla3[[#This Row],[Iniciales Documento]]) -> PMOTI_0410_CI_AAP | H36: =CONCATENATE(Tabla3[[#This Row],[Clave]]) -> PMOTI_0410_CI_AAP | I36: Acta de Aceptación de Proyecto | J36: =CONCATENATE(Tabla3[[#This Row],[Clave]]," ",Tabla3[[#This Row],[Entregables]]) -> PMOTI_0410_CI_AAP Acta de Aceptación de Proyecto | K36: PMOTI_0410_CI_AAP Acta de Aceptación de Proyecto.docx
A37: Cierre | B37: Docuentacion | C37: 4 | D37: =10+D36 -> 20 | E37: CI | F37: GDP | G37: =CONCATENATE("PMOTI","_","0",Tabla3[[#This Row],[No. Fase]],Tabla3[[#This Row],[Orden del documento]],"_",Tabla3[[#This Row],[Iniciales de la Fase]],"_",Tabla3[[#This Row],[Iniciales Documento]]) -> PMOTI_0420_CI_GDP | H37: =CONCATENATE(Tabla3[[#This Row],[Clave]]) -> PMOTI_0420_CI_GDP | I37: Gestión de Documentos del Proyecto | J37: =CONCATENATE(Tabla3[[#This Row],[Clave]]," ",Tabla3[[#This Row],[Entregables]]) -> PMOTI_0420_CI_GDP Gestión de Documentos del Proyecto
A38: Cierre | B38: Docuentacion | C38: 4 | D38: =10+D37 -> 30 | E38: CI | F38: JEC | G38: =CONCATENATE("PMOTI","_","0",Tabla3[[#This Row],[No. Fase]],Tabla3[[#This Row],[Orden del documento]],"_",Tabla3[[#This Row],[Iniciales de la Fase]],"_",Tabla3[[#This Row],[Iniciales Documento]]) -> PMOTI_0430_CI_JEC | H38: =CONCATENATE(Tabla3[[#This Row],[Clave]]) -> PMOTI_0430_CI_JEC | I38: Junta de Entregables de Cierre | J38: =CONCATENATE(Tabla3[[#This Row],[Clave]]," ",Tabla3[[#This Row],[Entregables]]) -> PMOTI_0430_CI_JEC Junta de Entregables de Cierre | K38: PMOTI_0430_CI_JEC Junta de Entregables de Cierre.docx
A39: Cierre | B39: Seguimiento y control | C39: 4 | D39: =10+D38 -> 40 | E39: CI | F39: SC | G39: =CONCATENATE("PMOTI","_","0",Tabla3[[#This Row],[No. Fase]],Tabla3[[#This Row],[Orden del documento]],"_",Tabla3[[#This Row],[Iniciales de la Fase]],"_",Tabla3[[#This Row],[Iniciales Documento]]) -> PMOTI_0440_CI_SC | H39: =CONCATENATE(Tabla3[[#This Row],[Clave]]) -> PMOTI_0440_CI_SC | I39: Solicitud de Cambio Nº | J39: =CONCATENATE(Tabla3[[#This Row],[Clave]]," ",Tabla3[[#This Row],[Entregables]]) -> PMOTI_0440_CI_SC Solicitud de Cambio Nº | K39: PMOTI_0440_CI_SC Solicitud de Cambio Nº.docx
A40: Cierre | B40: Seguimiento y control | C40: 4 | D40: =10+D39 -> 50 | E40: CI | F40: ID | G40: =CONCATENATE("PMOTI","_","0",Tabla3[[#This Row],[No. Fase]],Tabla3[[#This Row],[Orden del documento]],"_",Tabla3[[#This Row],[Iniciales de la Fase]],"_",Tabla3[[#This Row],[Iniciales Documento]]) -> PMOTI_0450_CI_ID | H40: =CONCATENATE(Tabla3[[#This Row],[Clave]]) -> PMOTI_0450_CI_ID | I40: Informe de Desempeño Nº | J40: =CONCATENATE(Tabla3[[#This Row],[Clave]]," ",Tabla3[[#This Row],[Entregables]]) -> PMOTI_0450_CI_ID Informe de Desempeño Nº | K40: PMOTI_0450_CI_ID Informe de Desempeño Nº.docx
A41: Cierre | B41: Seguimiento y control | C41: 4 | D41: =10+D40 -> 60 | E41: CI | F41: RC | G41: =CONCATENATE("PMOTI","_","0",Tabla3[[#This Row],[No. Fase]],Tabla3[[#This Row],[Orden del documento]],"_",Tabla3[[#This Row],[Iniciales de la Fase]],"_",Tabla3[[#This Row],[Iniciales Documento]]) -> PMOTI_0460_CI_RC | H41: =CONCATENATE(Tabla3[[#This Row],[Clave]]) -> PMOTI_0460_CI_RC | I41: Reunion de Control Nº | J41: =CONCATENATE(Tabla3[[#This Row],[Clave]]," ",Tabla3[[#This Row],[Entregables]]) -> PMOTI_0460_CI_RC Reunion de Control Nº | K41: PMOTI_0460_CI_RC Reunion de Control Nº.docx
A42: Cierre | B42: Cierre | C42: 4 | D42: =10+D41 -> 70 | E42: CI | F42: ACFC | G42: =CONCATENATE("PMOTI","_","0",Tabla3[[#This Row],[No. Fase]],Tabla3[[#This Row],[Orden del documento]],"_",Tabla3[[#This Row],[Iniciales de la Fase]],"_",Tabla3[[#This Row],[Iniciales Documento]]) -> PMOTI_0470_CI_ACFC | H42: =CONCATENATE(Tabla3[[#This Row],[Clave]]) -> PMOTI_0470_CI_ACFC | I42: Acta de Cierre de la Fase de Cierre | J42: =CONCATENATE(Tabla3[[#This Row],[Clave]]," ",Tabla3[[#This Row],[Entregables]]) -> PMOTI_0470_CI_ACFC Acta de Cierre de la Fase de Cierre | K42: PMOTI_0470_CI_ACFC Acta de Cierre de la Fase de Cierre.docx

Sheet Actividades
A1: Nombre del documento | B1: Actividad | C1: Nombre Completo | D1: Fecha | E1: Comentario | G1: Actividades
A2: Matriz | B2: Elaborp | C2: Morales Quiroz Daniel Alejandro | D2: 2025-09-12 | E2: Elabore el documento y agrege los nombres y la estructura del mismo | G2: elaboro
A3: PMOTI_0110_IN_ACP PROJECT CHARTER O ACTA DE CONSTITUCIÓN DEL PROYECTO | B3: Elaboro | C3: Morales Quiroz Daniel Alejandro | D3: 2025-09-19 | E3: Agregue el documento en su carpeta correspondiente asi como agregar el logo de la organizacion en el documento | G3: modifico
A4: PMOTI_0120_IN_EGI Estrategia de Gestión de Interesados | B4: Elaboro | C4: Morales Quiroz Daniel Alejandro | D4: 2025-09-19 | E4: Agregue el documento en su carpeta correspondiente asi como agregar el logo de la organizacion en el documento | G4: reviso
A5: PMOTI_0130_IN_JEI Junta de Entregables de Inicio | B5: Elaboro | C5: Morales Quiroz Daniel Alejandro | D5: 2025-09-19 | E5: Agregue el documento en su carpeta correspondiente asi como agregar el logo de la organizacion en el documento
A6: PMOTI_0140_IN_SC Solicitud de Cambio Nº | B6: Elaboro | C6: Morales Quiroz Daniel Alejandro | D6: 2025-09-19 | E6: Agregue el documento en su carpeta correspondiente asi como agregar el logo de la organizacion en el documento
A7: PMOTI_0150_IN_ID Informe de Desempeño Nº | B7: Elaboro | C7: Morales Quiroz Daniel Alejandro | D7: 2025-09-19 | E7: Agregue el documento en su carpeta correspondiente asi como agregar el logo de la organizacion en el documento
A8: PMOTI_0160_IN_ACFI Acta de Cierre de la Fase de Inicio | B8: Elaboro | C8: Morales Quiroz Daniel Alejandro | D8: 2025-09-19 | E8: Agregue el documento en su carpeta correspondiente asi como agregar el logo de la organizacion en el documento
A9: PMOTI_0210_PL_PGC Plan de Gestión de la Configuracion | B9: Elaboro | C9: Morales Quiroz Daniel Alejandro | D9: 2025-09-20 | E9: Agregue el documento en su carpeta correspondiente asi como agregar el logo de la organizacion en el documento
A10: PMOTI_0220_PL_PGC Plan de Gestión de Cambios | B10: Elaboro | C10: Morales Quiroz Daniel Alejandro | D10: 2025-09-20 | E10: Agregue el documento en su carpeta correspondiente asi como agregar el logo de la organizacion en el documento
A11: PMOTI_0230_PL_DA Declaración de Alcance | B11: Elaboro | C11: Morales Quiroz Daniel Alejandro | D11: 2025-09-20 | E11: Agregue el documento en su carpeta correspondiente asi como agregar el logo de la organizacion en el documento
A12: PMOTI_0240_PL_DR Documentación de Requisitos | B12: Elaboro | C12: Morales Quiroz Daniel Alejandro | D12: 2025-09-20 | E12: Agregue el documento en su carpeta correspondiente asi como agregar el logo de la organizacion en el documento
A13: PMOTI_0250_PL_PGR Plan de Gestión de Requisitos | B13: Elaboro | C13: Morales Quiroz Daniel Alejandro | D13: 2025-09-20 | E13: Agregue el documento en su carpeta correspondiente asi como agregar el logo de la organizacion en el documento
A14: PMOTI_0260_PL_MTR Matriz de Trazabilidad de Requisitos | B14: Elaboro | C14: Morales Quiroz Daniel Alejandro | D14: 2025-09-20 | E14: Agregue el documento en su carpeta correspondiente asi como agregar el logo de la organizacion en el documento
A15: PMOTI_0270_PL_PGP Plan de Gestión de Proyecto | B15: Elaboro | C15: Morales Quiroz Daniel Alejandro | D15: 2025-09-20 | E15: Agregue el documento en su carpeta correspondiente asi como agregar el logo de la organizacion en el documento
A16: PMOTI_0280_PL_PGA Plan de Gestión de Alcance | B16: Elaboro | C16: Morales Quiroz Daniel Alejandro | D16: 2025-09-20 | E16: Agregue el documento en su carpeta correspondiente asi como agregar el logo de la organizacion en el documento
... A43: PMOTI_0470_CI_ACFC Acta de Cierre de la Fase de Cierre | B43: Elaboro | C43: Morales Quiroz Daniel Alejandro | D43: 2025-09-20 | E43: Agregue el documento en su carpeta correspondiente asi como agregar el logo de la organizacion en el documento
A44: PMOTI_0110_IN_ACP PROJECT CHARTER O ACTA DE CONSTITUCIÓN DEL PROYECTO | B44: Reviso | C44: Solis Espinoza Cristian Eduardo | D44: 2025-09-21
A45: PMOTI_0120_IN_EGI Estrategia de Gestión de Interesados | B45: Reviso | C45: Solis Espinoza Cristian Eduardo | D45: 2025-09-21
A46: PMOTI_0130_IN_JEI Junta de Entregables de Inicio | B46: Reviso | C46: Solis Espinoza Cristian Eduardo | D46: 2025-09-21
A47: PMOTI_0140_IN_SC Solicitud de Cambio Nº | B47: Reviso | C47: Solis Espinoza Cristian Eduardo | D47: 2025-09-21
A48: PMOTI_0150_IN_ID Informe de Desempeño Nº | B48: Reviso | C48: Solis Espinoza Cristian Eduardo | D48: 2025-09-21
A49: PMOTI_0160_IN_ACFI Acta de Cierre de la Fase de Inicio | B49: Reviso | C49: Solis Espinoza Cristian Eduardo | D49: 2025-09-21
A50: PMOTI_0210_PL_PGC Plan de Gestión de la Configuracion | B50: Reviso | C50: Solis Espinoza Cristian Eduardo | D50: 2025-09-21
A51: PMOTI_0220_PL_PGC Plan de Gestión de Cambios | B51: Reviso | C51: Solis Espinoza Cristian Eduardo | D51: 2025-09-21
A52: PMOTI_0230_PL_DA Declaración de Alcance | B52: Reviso | C52: Solis Espinoza Cristian Eduardo | D52: 2025-09-21
A53: PMOTI_0240_PL_DR Documentación de Requisitos | B53: Reviso | C53: Solis Espinoza Cristian Eduardo | D53: 2025-09-21
A54: PMOTI_0250_PL_PGR Plan de Gestión de Requisitos | B54: Reviso | C54: Solis Espinoza Cristian Eduardo | D54: 2025-09-21
A55: PMOTI_0260_PL_MTR Matriz de Trazabilidad de Requisitos | B55: Reviso | C55: Solis Espinoza Cristian Eduardo | D55: 2025-09-21
... A70: PMOTI_02210_PL_ACFP Acta de Cierre de la Fase de Planeación | B70: Reviso | C70: Solis Espinoza Cristian Eduardo | D70: 2025-09-21
A71: Matriz | B71: Modifico | C71: Morales Quiroz Daniel Alejandro | D71: 2025-09-22 | E71: Agrege la hoja actividades para el control de actividades
A72: =Matriz!J8 -> PMOTI_0210_PL_PGC Plan de Gestión de la Configuracion | B72: Modifico | C72: Ruiz Dominguez Abdiel Efrain | D72: 2025-09-22 | E72: Correción de nombre e imagen de Project Management borrada.
A73: =Matriz!J9 -> PMOTI_0220_PL_PGC Plan de Gestión de Cambios | B73: Modifico | C73: Ruiz Dominguez Abdiel Efrain | D73: 2025-09-22 | E73: Correción de nombre e imagen de Project Management borrada.
A74: =Matriz!J10 -> PMOTI_0230_PL_DA Declaración de Alcance | B74: Modifico | C74: Ruiz Dominguez Abdiel Efrain | D74: 2025-09-22 | E74: Correción de nombre e imagen de Project Management borrada.
A75: =Matriz!J11 -> PMOTI_0240_PL_DR Documentación de Requisitos | B75: Modifico | C75: Ruiz Dominguez Abdiel Efrain | D75: 2025-09-22 | E75: Correción de nombre e imagen de Project Management borrada.
A76: =Matriz!J12 -> PMOTI_0250_PL_PGR Plan de Gestión de Requisitos | B76: Modifico | C76: Ruiz Dominguez Abdiel Efrain | D76: 2025-09-22 | E76: Correción de nombre e imagen de Project Management borrada.
A77: =Matriz!J13 -> PMOTI_0260_PL_MTR Matriz de Trazabilidad de Requisitos | B77: Modifico | C77: Ruiz Dominguez Abdiel Efrain | D77: 2025-09-22 | E77: Correción de nombre e imagen de Project Management borrada.
A78: =Matriz!J14 -> PMOTI_0270_PL_PGP Plan de Gestión de Proyecto | B78: Modifico | C78: Ruiz Dominguez Abdiel Efrain | D78: 2025-09-22 | E78: Correción de nombre e imagen de Project Management borrada.
A79: =Matriz!J15 -> PMOTI_0280_PL_PGA Plan de Gestión de Alcance | B79: Modifico | C79: Ruiz Dominguez Abdiel Efrain | D79: 2025-09-22 | E79: Correción de nombre e imagen de Project Management borrada.
A80: =Matriz!J16 -> PMOTI_0290_PL_EDT EDT | B80: Modifico | C80: Ruiz Dominguez Abdiel Efrain | D80: 2025-09-22 | E80: Correción de nombre e imagen de Project Management borrada.
...
